Workbook

Sheet راهنما
A1: راهنمای استفاده از این فایل
A3: موضوع | B3: توافق Fit-Gap پایلوت صدای کارکنان (EX) — MCINEXT × اداره تجربه کارکنان همراه اول
A4: تعداد نیازمندی | B4: ۸۷ ردیف در ۸ بلوک
A5: مبنای ستون «وضعیت تأییدشده» | B5: خوانش مستقیم کد مخزن phoenix — فقط پروژه‌های پایتونِ فعال در ۳ ماه گذشته
A6: تاریخ بررسی کد | B6: ۱۴۰۵/۰۷/۰۶ — معادل 2026-09-28
A7: دامنه بررسی | B7: coa-api, aiva, adcs, aqa, chatbot-iva-agent, agentlib, adcs-auth, adcs-knowledgebase, aiva-knowledgebase, fastlib
A8: خارج از دامنه | B8: python/coa-ai — موتور تحلیل احساسات/خلاصه/موضوع. آخرین کامیت 2025-07-13 (۱۴ ماه فریز)
A10: ستون‌هایی که شما پر می‌کنید | B10: «اولویت EX» را EX پر می‌کند. «ددلاین نهایی» را شما بر اساس ستون «ددلاین پیشنهادی» تثبیت می‌کنید.
A11: قاعده ددلاین | B11: هیچ تاریخ تقویمی ننویسید. بنویسید «T + n روز کاری از دریافت [ورودی مشخص]». مبنای این قاعده معیار پذیرش خودِ ردیف TEC-14 است.
A13: معنای رنگ‌ها
A14: سبز — تأییدشده | B14: در کد پیدا شد و کار می‌کند. قابل دفاع در UAT.
A15: زرد — جزئی | B15: بخشی پیاده شده. بدون توضیح، در UAT رد می‌شود.
A16: قرمز — رد شد | B16: ادعای توافق با کد نمی‌خواند. پیش از جلسه اصلاح کنید.
A17: طوسی — غایب | B17: هیچ کدی وجود ندارد. توسعه واقعی لازم است.
A18: آبی — خالی | B18: ستون در توافق خالی مانده و باید پر شود.
A19: بدون رنگ — تنظیم/زیرساخت | B19: کد لازم نیست؛ Configuration یا فرایند است.
A21: نمونه سطر پرشده | B21: مثال: PRV-03 | ادعا: موجود در محصول | تأییدشده: رد شد | شاهد: coa/apps/files/views.py:19 | ددلاین: پیش از UAT، T+3 روز کاری

Sheet ردیف‌ها
A1: بلوک | B1: ID | C1: نیازمندی | D1: شرح نیاز / رفتار مورد انتظار | E1: سناریو یا معیار پذیرش | F1: اولویت EX | G1: وضعیت اعلامی MCINEXT | H1: وضعیت تأییدشده با کد | I1: شاهد در کد (file:line) | J1: اطمینان | K1: مالک وابستگی | L1: ددلاین پیشنهادی | M1: اقدام لازم / ریسک | N1: توضیحات فنی توافق | O1: ددلاین نهایی
A2: 1. Voice Intake & Access | B2: VIA-01 | C2: سرشماره / کانال صوتی Inbound | D2: یک کانال صوتی مشخص برای EX ایجاد شود تا کارکنان Whitelist‌شده بتوانند مستقیماً با AI تماس بگیرند. کانال باید مستقل از محیط عمومی Contact Center قابل استفاده و قابل ردیابی باشد. | E2: شماره پایلوت از یک شماره مجاز تماس می‌گیرد و بدون اپراتور انسانی وارد مکالمه AI می‌شود. | G2: نیازمند تنظیم / Configuration | H2: تنظیم / زیرساخت | I2: chatbot-iva-agent/src/config.py (AGENT_SIP_*, AGENT_ORIGINAL_CALL_ID_FALLBACK); src/entrypoint.py | J2: قطعی | K2: MCINEXT + MCI-IT | L2: T+5 روز کاری پس از تخصیص سرشماره و Virtual IP | M2: مسیر SIP و هدرهای x-originalcallid/city_code پیاده‌سازی شده؛ فقط تخصیص سرشماره و اتصال Kamailio باقی است
A3: 1. Voice Intake & Access | B3: VIA-02 | C3: Whitelist کارکنان MCI | D3: فقط شماره‌های متعلق به کارکنان با قرارداد MCI که در دیتاست تأییدشده قرار دارند اجازه ورود به سرویس پایلوت را داشته باشند. | E3: تماس شماره داخل Whitelist وارد سرویس می‌شود؛ شماره خارج از Whitelist وارد Flow اصلی نمی‌شود. | G3: نیازمند تنظیم / Configuration | H3: جزئی | I3: aiva/memory/config.py:20-21 (PHONE_WHITELIST=[], BYPASS_WHITELIST=True); aiva_consume_kafka.py:310 | J3: قطعی | K3: MCINEXT | L3: T+7 روز کاری پس از دریافت دیتاست شماره‌ها از EX | M3: ⚠️ Whitelist موجود فقط «جمع‌آوری memory» را گیت می‌کند، نه «ورود تماس». گیت پذیرش تماس باید در لایه SIP اضافه شود. ضمناً BYPASS_WHITELIST پیش‌فرض True است
A4: 1. Voice Intake & Access | B4: VIA-03 | C4: رفتار برای شماره خارج از Whitelist | D4: برای شماره غیرمجاز رفتار شفاف و کنترل‌شده تعریف شود؛ مانند پیام کوتاه عدم دسترسی، بدون افشای اطلاعات داخلی یا ایجاد رکورد تحلیلی اشتباه. | E4: یک شماره غیرمجاز تست شود و پیام صحیح دریافت کند؛ تماس به‌عنوان Voice کارکنان ثبت نشود. | G4: نیازمند بررسی فنی | H4: غایب | I4: جست‌وجو در ۸ سرویس: هیچ مسیر رد تماس غیرمجاز یافت نشد | J4: قطعی | K4: MCINEXT | L4: T+5 روز کاری پس از تعریف پیام توسط EX | M4: نیاز به پیام کوتاه و مسیر قطع در لایه SIP/Agent، بدون ایجاد رکورد تحلیلی
A5: 1. Voice Intake & Access | B5: VIA-04 | C5: دریافت شماره تماس به‌عنوان کلید Mapping | D5: شماره تماس صرفاً برای شناسایی رکورد کارمند و اتصال Context سازمانی دریافت شود؛ شماره نباید به‌صورت پیش‌فرض در Dashboard تحلیلی دیده شود. | E5: شماره کارمند به رکورد صحیح Mapping می‌شود ولی در View تحلیلی نام/شماره نمایش داده نمی‌شود. | G5: نیازمند توسعه / Customization | H5: جزئی | I5: chatbot-iva-agent/src/schema.py (phone_number); coa/apps/main/models.py:381 (user_num) | J5: قطعی | K5: MCINEXT | L5: T+10 روز کاری پس از تصمیم سیاست هویت | M5: شماره هم در payload کافکا و هم در DB به‌صورت plaintext ذخیره می‌شود؛ پنهان‌سازی در Serializer/View نیازمند توسعه است
A6: 1. Voice Intake & Access | B6: VIA-05 | C6: Mapping شماره به اطلاعات سازمانی | D6: سیستم بتواند از طریق دیتاست مورد تأیید، شماره را به اطلاعات لازم سازمانی مانند معاونت، اداره کل و اداره متصل کند. | E6: یک تماس آزمایشی در تحلیل با Segment سازمانی صحیح نمایش داده شود. | G6: نیازمند توسعه / Customization | H6: غایب | I6: هیچ جدول Mapping شماره→ساختار سازمانی یافت نشد | J6: قطعی | K6: مشترک (دیتاست از EX) | L6: T+10 روز کاری پس از دریافت دیتاست سازمانی | M6: نیاز به مدل داده Mapping (معاونت/اداره کل/اداره) + سرویس Lookup
A7: 1. Voice Intake & Access | B7: VIA-06 | C7: ثبت Metadata تماس | D7: برای هر تماس شناسه یکتا، تاریخ و ساعت، مدت تماس و وضعیت تکمیل/قطع تماس ثبت شود تا تحلیل و Audit ممکن باشد. | E7: هر تماس یک Conversation ID یکتا و Metadata کامل قابل مشاهده در Backend داشته باشد. | G7: نیازمند توسعه / Customization | H7: جزئی | I7: chatbot-iva-agent/src/schema.py (session_id, call_id, original_call_id, session_duration, agent_prewarmed/started/ended_time); coa/apps/main/models.py:166 | J7: قطعی | K7: MCINEXT | L7: T+5 روز کاری (تگ تکمیل/قطع: پس از تعریف EX) | M7: شناسه یکتا، زمان و مدت کامل موجود است؛ فقط تگ Incomplete/Complete باقی مانده — بخش عمده این ردیف «موجود» است | N7: برخی موارد مانند شناسه یکتا و تاریخ و ساعت از قبل در سامانه موجود است ولی وضعیت تکمیل یا قطع تماس نیازمند ارائه تعریف مشخص و واضح جهت ایجاد تگ می‌باشد که در فاز فعلی اولویت ندارد. همچنین جستجو روی Metadata نیازمند ارائه نمونه و توسعه از سمت تیم MCINEXT است.
A8: 1. Voice Intake & Access | B8: VIA-07 | C8: مدیریت تماس قطع‌شده یا ناقص | D8: اگر تماس قبل از پایان قطع شد، سیستم آن را Incomplete علامت بزند و فقط بخش واقعاً دریافت‌شده را ذخیره کند؛ AI نباید اطلاعات نگفته را تکمیل یا حدس بزند. | E8: تماس عمداً قطع شود؛ رکورد Incomplete ایجاد شود و Summary ساختگی تولید نشود. | G8: نیازمند بررسی فنی | H8: غایب | I8: هیچ گارد min_duration/min_turns پیش از خلاصه‌سازی یافت نشد | J8: قطعی | K8: MCINEXT | L8: گارد: T+3 روز کاری | تگ Incomplete: پس از تعریف EX | M8: ⚠️ Red Flag: احتمال تولید Summary از تماس قطع‌شده. گارد حداقل مدت/نوبت را همین فاز اضافه کنید حتی اگر تگ به تأخیر بیفتد | N8: وضعیت تکمیل یا قطع تماس نیازمند ارائه تعریف مشخص و واضح جهت ایجاد تگ می‌باشد که در فاز فعلی اولویت ندارد.
A9: 1. Voice Intake & Access | B9: VIA-08 | C9: پایداری و کیفیت سرویس صوتی | D9: کانال در محدوده ظرفیت Pilot باید کیفیت و پایداری کافی داشته باشد و خطاهای اتصال، قطع تماس یا Failure ثبت شوند. | E9: چند تماس متوالی و هم‌زمان Pilot بدون از دست‌رفتن رکورد اجرا شوند و Error Log در دسترس تیم فنی باشد. | G9: موجود در محصول | H9: تأییدشده | I9: chatbot-iva-agent/src/config.py (AGENT_MAX_UNRECOVERABLE_ERRORS, STT/LLM/TTS retry+timeout); src/utils/prometheus_metrics.py; src/utils/apm.py | J9: قطعی | K9: MCINEXT | L9: — | M9: Retry، timeout، Prometheus و Elastic APM کامل است. ظرفیت هم‌زمانی پایلوت باید با Load Test تثبیت شود
A10: 2. Conversation Experience | B10: CON-01 | C10: معرفی کوتاه AI و هدف کانال | D10: در ابتدای تماس AI به‌صورت کوتاه و شفاف خود را معرفی کند و بگوید کانال برای شنیدن تجربه، مسئله، پیشنهاد و سؤال کارکنان است. | E10: Intro کوتاه، قابل فهم و بدون متن حقوقی طولانی اجرا شود. | G10: موجود در محصول | H10: تأییدشده | I10: chatbot-iva-agent/src/config.py (AGENT_GREETING_MESSAGE, AGENT_GREETING_ALLOW_INTERRUPTION) | J10: قطعی | K10: EX (متن) | L10: T+1 روز کاری پس از تأیید متن | M10: متن معرفی کاملاً قابل تنظیم است
A11: 2. Conversation Experience | B11: CON-02 | C11: Privacy Notice کوتاه | D11: در ابتدای تعامل، نحوه کلی استفاده از مکالمه و اینکه داده برای تحلیل تجربه کارکنان استفاده می‌شود به کارمند اعلام شود. | E11: کاربر قبل از بیان محتوای اصلی، Notice تأییدشده EX را می‌شنود. | G11: موجود در محصول | H11: تنظیم | I11: همان AGENT_GREETING_MESSAGE | J11: قطعی | K11: EX | L11: T+1 روز کاری پس از تأیید متن Notice | M11: فقط متن؛ هیچ کد جدیدی لازم نیست
A12: 2. Conversation Experience | B12: CON-03 | C12: شروع Open-ended | D12: مکالمه با یک سؤال باز آغاز شود و کارمند مجبور به انتخاب منو یا طبقه‌بندی Voice خود نباشد. | E12: کارمند بتواند هر موضوعی را با زبان طبیعی مطرح کند بدون اینکه ابتدا Category انتخاب کند. | G12: موجود در محصول | H12: تأییدشده | I12: aiva/prompts/greeting.py; aiva/prompts/react.py | J12: قطعی | K12: — | L12: — | M12: شروع آزاد و بدون منو
A13: 2. Conversation Experience | B13: CON-04 | C13: Follow-up هوشمند در صورت ابهام | D13: AI فقط زمانی سؤال تکمیلی بپرسد که برای فهم موضوع Gap واقعی وجود دارد؛ سؤال باید Neutral، مرتبط و مبتنی بر صحبت قبلی فرد باشد. | E13: برای جمله مبهم «فرایند ارزیابی خوب نیست» AI سؤال روشن‌کننده مرتبط بپرسد. | G13: موجود در محصول | H13: تأییدشده | I13: aiva/chat/handlers/clarifying.py; aiva/chat/handlers/classification.py; aiva/prompts/clarifying_chitchat.py | J13: قطعی | K13: — | L13: — | M13: شاخه clarifying با classifier مستقل؛ معماری در docs/RequestFlow.md
A14: 2. Conversation Experience | B14: CON-05 | C14: عدم تکرار سؤال | D14: AI اطلاعاتی را که کارمند قبلاً در همان Conversation گفته دوباره سؤال نکند و Context مکالمه را حفظ کند. | E14: در سناریوی UAT، اطلاعات گفته‌شده مجدداً درخواست نشود. | G14: موجود در محصول | H14: تأییدشده | I14: aiva/chat/config.py (CHAT_HISTORY_LIMIT=50); docs/RequestFlow.md (ChatContext مشترک) | J14: قطعی | K14: — | L14: — | M14: حفظ Context در طول Conversation ⚠️ AIVA علاوه بر Context تماس، Long-term Memory بین تماس‌ها برای هر شماره می‌سازد (aiva/memory، ChatbotUser.memory) — باید در Notice اعلام یا برای EX خاموش شود.
A15: 2. Conversation Experience | B15: CON-06 | C15: محدودیت Follow-up | D15: مکالمه نباید به مصاحبه طولانی یا بازجویی تبدیل شود. تعداد/منطق Follow-up قابل کنترل باشد و پس از فهم کافی مکالمه جمع‌بندی شود. | E15: برای Conversation عادی، تعداد Follow-up از سقف توافق‌شده در UAT عبور نکند. | G15: موجود در محصول | H15: جزئی | I15: aiva/chat/config.py (REACT_MAX_ITERS=10, AGENT_MAX_HISTORY_TURNS=6) | J15: قطعی | K15: MCINEXT | L15: T+3 روز کاری | M15: سقف حلقه ابزار و تاریخچه موجود است اما «سقف تعداد Follow-up» به‌عنوان پارامتر مستقل وجود ندارد
A16: 2. Conversation Experience | B16: CON-07 | C16: تشخیص Voice کامل و عدم سؤال اضافه | D16: اگر کارمند از ابتدا موضوع، زمان/زمینه و اثر مسئله را روشن توضیح داده، AI فقط به‌دلیل قابلیت مکالمه سؤال اضافه نپرسد. | E16: سناریوی کامل تست شود و Unnecessary Follow-up رخ ندهد. | G16: موجود در محصول | H16: تأییدشده | I16: aiva/prompts/classification.py:88; aiva/prompts/clarifying_chitchat.py:48 | J16: قطعی | K16: — | L16: — | M16: تشخیص Voice کامل در Prompt طبقه‌بندی لحاظ شده
A17: 2. Conversation Experience | B17: CON-08 | C17: Summary Confirmation در صورت امکان | D17: در صورت پشتیبانی محصول، AI بتواند قبل از پایان برداشت کوتاه خود را بازگو کند تا فرد آن را تأیید یا اصلاح کند. | E17: کاربر بتواند Summary را تأیید یا یک نکته مهم را اصلاح کند. | G17: نیازمند تنظیم / Configuration | H17: غایب | I17: — | J17: قطعی | K17: EX (بازتعریف) | L17: معلق تا بازتعریف EX | M17: خود توافق این ردیف را «نیازمند بازبینی» دانسته؛ تعهد ندهید | N17: این مورد به دلیل عدم خوش تعریفی و عدم امکان تعریف روش صحیح سوال پرسیدن در حین تماس، احتیاج به بازبینی دارد.
A18: 2. Conversation Experience | B18: CON-09 | C18: پایان شفاف بدون وعده پیگیری فردی | D18: Closing Message دریافت Voice را تأیید کند، اما چون MVP برای رسیدگی فردی طراحی نشده، SLA یا وعده پاسخ شخصی ایجاد نکند. | E18: هیچ عبارت «ظرف X ساعت پیگیری می‌شود» یا وعده خارج از Scope شنیده نشود. | G18: موجود در محصول | H18: تأییدشده | I18: aiva/chat/config.py (TOOL_CALLING_EXIT_ANSWER, exit_tool); INTENT_AGENT_ENABLED_TOOLS | J18: قطعی | K18: — | L18: — | M18: پایان شفاف بدون وعده SLA
A19: 3. AI Analysis | B19: AI-01 | C19: Speech-to-Text فارسی | D19: مکالمه فارسی با کیفیت قابل قبول به متن تبدیل شود و کیفیت آن روی نوع بیان واقعی کارکنان، نه فقط نمونه‌های استودیویی، سنجیده شود. | E19: مجموعه سناریوهای UAT با لهجه/سرعت طبیعی اجرا و خطاهای STT ثبت شوند. | G19: موجود در محصول | H19: تأییدشده | I19: chatbot-iva-agent/src/utils/stt.py + AGENT_STT_MODEL/BASE_URL; adcs POST /api/v1/chat/asr | J19: قطعی | K19: MCINEXT | L19: — | M19: ⚠️ پیاده‌سازی شده اما WER هرگز اندازه‌گیری نشده. «موجود» یعنی implemented نه measured | N19: این بخش جزئی از کل یک سرویس می‌باشد و بهبود کیفیت بر عهده تیم MCINEXT است و نیازی به بررسی تک تک مکالمات از سوی EX نمی‌باشد.
A20: 3. AI Analysis | B20: AI-02 | C20: Transcript کامل مکالمه | D20: متن Conversation به شکلی قابل بازیابی برای کاربران مجاز ذخیره شود و ارتباط آن با Conversation ID حفظ شود. | E20: Transcript هر تماس تکمیل‌شده در Backend موجود و به تماس صحیح متصل باشد. | G20: فعلاً خارج از Scope | H20: رد شد (ادعا نادرست) | I20: coa/apps/main/models.py:397 (raw_input); services/call.py:771 ("asr_data": raw_input if debug); models.py:395 (conversation_reform); chatbot-iva-agent/src/schema.py (messages[].text) | J20: قطعی | K20: مشترک (تصمیم سیاست) | L20: T+2 روز کاری برای تصمیم سیاست | M20: ⚠️⚠️ Transcript ذخیره می‌شود و روی Kafka منتشر می‌شود. «خارج از Scope» نادرست است. یا نگهداری را اعلام کنید یا ذخیره را متوقف کنید
A21: 3. AI Analysis | B21: AI-03 | C21: Summary Fact-based | D21: AI برای هر مکالمه یا Voice Item خلاصه کوتاهی تولید کند که فقط آنچه فرد گفته بازتاب دهد و علت/قضاوت جدید اختراع نکند. | E21: Human Reviewer بتواند Summary را با Transcript مقایسه و Faithfulness آن را تأیید کند. | G21: موجود در محصول | H21: تأییدشده | I21: coa/apps/main/models.py:372 (call_summary); chatbot-iva-agent AGENT_LLM_SESSION_SUMMARY_URL | J21: قطعی | K21: MCINEXT | L21: — | M21: ⚠️ معیار پذیرش این ردیف مقایسه با Transcript است — به AI-02 گره خورده. Faithfulness سنجیده نشده | N21: معیار پذیرش از طریق شنیدن مکالمه و بررسی خلاصه تماس امکان پذیر است.
A22: 3. AI Analysis | B22: AI-04 | C22: تفکیک چند موضوع در یک مکالمه | D22: اگر کارمند در یک تماس چند مسئله مستقل مطرح کرد، سیستم آن‌ها را به Voice Itemهای جداگانه تفکیک کند تا هر موضوع Coding مستقل داشته باشد. | E22: سناریوی غذا + ارتقا + پرتال حداقل به سه Voice Item مجزا شکسته شود. | G22: موجود در محصول | H22: نامشخص (coa-ai فریز) | I22: coa/apps/main/models.py:396 (topics JSON), 370 (category_subcategory_dict) — فقط خواندن نتیجه | J22: محتمل | K22: MCINEXT | L22: T+15 روز کاری پس از بازفعال‌سازی coa-ai | M22: منطق تفکیک چندموضوعی در python/coa-ai است که آخرین کامیتش 2025-07-13 است | N22: در سامانه تحلیل هوشمند به صورت خودکار به صورت جداگانه تشخیص داده می‌شوند.
A23: 3. AI Analysis | B23: AI-05 | C23: تشخیص نوع Voice | D23: نوع پیام مانند پیشنهاد، Pain Point، شکایت، نگرانی، سؤال/ابهام یا تجربه مثبت تشخیص داده شود؛ در صورت نیاز Multi-label باشد. | E23: پیامی که هم Pain Point و هم Suggestion دارد، هر دو جنبه را از دست ندهد. | G23: نیازمند تنظیم / Configuration | H23: نامشخص (coa-ai فریز) | I23: coa/config.py (schema تگ‌ها) | J23: محتمل | K23: مشترک | L23: T+15 روز کاری پس از تعریف دقیق EX | M23: Multi-label بودن قابل تأیید نشد | N23: نیازمند تعریف دقیق‌تر
A24: 3. AI Analysis | B24: AI-06 | C24: Theme Detection | D24: موضوع اصلی هر Voice Item بر اساس Taxonomy مورد توافق EX شناسایی شود. | E24: Coding AI روی نمونه‌های Human-coded با تیم EX مقایسه شود. | G24: موجود در محصول | H24: نامشخص (coa-ai فریز) | I24: category_subcategory_dict; GET /api/v1/analyse/calls/Thematic-analysis/category | J24: محتمل | K24: مشترک (Taxonomy از EX) | L24: T+10 روز کاری پس از دریافت Taxonomy | M24: لایه سرویس‌دهی و گزارش کامل است؛ کیفیت Coding سنجیده نشده | N24: امکان ارائه لیست ابتدایی بابت موضوعات مختلف از تیم EX به تیم MCINEXT وجود دارد.
A25: 3. AI Analysis | B25: AI-07 | C25: Sub-theme Detection | D25: در صورت وجود ساختار زیرموضوع، AI Voice را در Sub-theme مناسب قرار دهد تا گزارش بیش از حد کلی نشود. | E25: برای Voice رستوران، زیرموضوعی مانند کیفیت/تنوع در صورت تعریف Taxonomy تشخیص داده شود. | G25: موجود در محصول | H25: نامشخص (coa-ai فریز) | I25: GET /api/v1/analyse/calls/Thematic-analysis/subcategory | J25: محتمل | K25: مشترک | L25: همان AI-06 | M25: زیرموضوع در API و مدل داده پشتیبانی می‌شود | N25: موجود در سامانه که به صورت خودکار ایجاد می‌کند.
A26: 3. AI Analysis | B26: AI-08 | C26: Sentiment / Direction | D26: جهت کلی محتوای Voice در سطح Positive / Neutral-Mixed / Negative تحلیل شود؛ مبنا محتوای بیان‌شده باشد نه ادعای قطعی درباره حالت روانی فرد. | E26: جهت کلی محتوای Voice در سطح Positive / Neutral-Mixed / Negative تحلیل شود؛ مبنا محتوای بیان‌شده باشد نه ادعای قطعی درباره حالت روانی فرد. | G26: نیازمند توسعه / Customization | H26: جزئی → «تنظیم» نه «توسعه» | I26: coa/apps/main/models.py:340-345 (user_sentiment, agent_sentiment, *_meta, index دار) | J26: قطعی | K26: MCINEXT | L26: T+5 روز کاری | M26: Sentiment از قبل ذخیره می‌شود؛ فقط مقیاس سه‌سطحی و عبارت‌بندی «مبتنی بر محتوا» نیاز به تنظیم دارد. ⚠️ سلول معیار پذیرش این ردیف کپی شرح نیاز است — از EX معیار واقعی بخواهید
A27: 3. AI Analysis | B27: AI-09 | C27: Positive Signal Detection | D27: سیستم علاوه بر مشکلات و نارضایتی‌ها، تجربه‌های مثبت و بهبودهای دیده‌شده توسط کارکنان را نیز استخراج کند. | E27: بازخورد مثبت درباره یک خدمت در Dashboard/Report قابل مشاهده باشد. | G27: موجود در محصول | H27: جزئی | I27: user_sentiment (مقادیر مثبت) + models.py:373 (suggestions) | J27: محتمل | K27: MCINEXT | L27: T+5 روز کاری | M27: داده هست؛ View/فیلتر اختصاصی Positive لازم است
A28: 3. AI Analysis | B28: AI-10 | C28: Frequency Analysis | D28: تعداد و سهم Voiceهای مرتبط با Theme/Sub-theme در بازه زمانی محاسبه شود تا موضوعات پرتکرار مشخص شوند. | E28: Top Themeها براساس واحد تحلیل مشخص و Denominator شفاف گزارش شوند. | G28: موجود در محصول | H28: تأییدشده | I28: coa/apps/main/services/thematic_analysis.py; /analyse/calls/Thematic-analysis/* | J28: قطعی | K28: — | L28: — | M28: Frequency و سهم موضوعات کامل
A29: 3. AI Analysis | B29: AI-11 | C29: Trend Detection | D29: سیستم تغییر موضوعات در زمان را تشخیص دهد و Rising/Stable/Falling یا روند مشابه ارائه کند؛ صرف Volume بالا به معنی Alert نباشد. | E29: موضوعی با رشد محسوس نسبت به Baseline به‌عنوان Rising شناسایی شود. | G29: موجود در محصول | H29: تأییدشده | I29: coa/apps/trends/services/sync.py; coa/apps/trends/models.py:81 (trend_score, baseline, trend_signal, is_trend, time_series) | J29: قطعی | K29: — | L29: — | M29: Baseline و signal واقعی دارد — نه فقط شمارش حجم
A30: 3. AI Analysis | B30: AI-12 | C30: Similarity & Clustering | D30: Voiceهای مشابه بدون حذف رکورد اصلی در Clusterهای مشترک قرار گیرند تا Patternهای تکرارشونده قابل مشاهده شوند. | E30: چند بازخورد مشابه درباره دسترسی روز اول در یک Cluster مشترک دیده شوند. | G30: موجود در محصول | H30: غایب (در ریپوهای فعال) | I30: هیچ کد clustering/similarity یافت نشد | J30: قطعی | K30: MCINEXT | L30: T+20 روز کاری | M30: یا در coa-ai فریزشده است یا وجود ندارد؛ پیش از تعهد بررسی شود | N30: نیازمند تعریف دقیق‌تر از سوی تیم EX
A31: 3. AI Analysis | B31: AI-13 | C31: Emerging Theme Detection | D31: سیستم بتواند موضوع جدیدی را که در Taxonomy موجود نیست ولی چند Voice مشابه درباره آن شکل گرفته شناسایی و به‌عنوان Candidate نمایش دهد. | E31: موضوع جدید به‌زور به نزدیک‌ترین Theme موجود Map نشود و Candidate قابل Review ایجاد شود. | G31: موجود در محصول | H31: غایب (در ریپوهای فعال) | I31: هیچ کد emerging/candidate topic یافت نشد | J31: قطعی | K31: MCINEXT | L31: T+20 روز کاری | M31: همین وضعیت AI-12
A32: 3. AI Analysis | B32: AI-14 | C32: Confidence / عدم اطمینان مدل | D32: در صورت امکان Confidence خروجی‌های اصلی ثبت شود و AI در موارد مبهم بتواند Unclear / Needs Review بدهد، نه اینکه Classification قطعی بسازد. | E32: نمونه صوت یا متن مبهم به‌عنوان Low Confidence/Needs Review قابل تشخیص باشد. | G32: نیازمند توسعه / Customization | H32: جزئی | I32: chatbot-iva-agent/src/schema.py (transcript_confidence per utterance) | J32: قطعی | K32: MCINEXT | L32: T+10 روز کاری | M32: Confidence در سطح ASR از قبل روی Kafka جریان دارد؛ Confidence خروجی LLM و برچسب Needs Review غایب است
A33: 3. AI Analysis | B33: AI-15 | C33: Severity / اهمیت بالقوه | D33: در صورت امکان، شدت موضوع از Sentiment جداگانه تشخیص داده شود تا یک محتوای آرام ولی مهم از یک شکایت کم‌اهمیت متمایز شود. | E33: یک موضوع دارای پیامد جدی بتواند Severity بالاتر از Sentiment آن دریافت کند. | G33: نیازمند توسعه / Customization | H33: غایب | I33: هیچ فیلد severity مستقل از sentiment یافت نشد | J33: قطعی | K33: مشترک | L33: T+15 روز کاری | M33: trends/services/webhook.py:93 فقط severity ثابت "high" دارد
A34: 4. Segmentation & Employee Context | B34: SEG-01 | C34: دریافت دیتاست معتبر کارکنان MCI | D34: برای Pilot یک دیتاست کنترل‌شده شامل شماره تماس و Attributeهای موردنیاز کارکنان MCI در اختیار سیستم قرار گیرد. | E34: نسخه اولیه دیتاست بدون فیلدهای غیرضروری بارگذاری و قابل Mapping باشد. | G34: نیازمند تنظیم / Configuration | H34: تنظیم | I34: — | J34: قطعی | K34: EX | L34: T+3 روز کاری پس از تحویل دیتاست | M34: وابستگی کامل به EX
A35: 4. Segmentation & Employee Context | B35: SEG-02 | C35: ساختار سازمانی موردنیاز | D35: حداقل فیلدهای معاونت، اداره کل و اداره برای تحلیل Segmentها قابل استفاده باشند؛ Attribute اضافه فقط در صورت نیاز واقعی وارد شود. | E35: Voice هر تماس در Segment سازمانی صحیح Aggregate شود. | G35: نیازمند تنظیم / Configuration | H35: تنظیم | I35: — | J35: قطعی | K35: EX | L35: همان SEG-01 | M35: حداقل سه فیلد سازمانی
A36: 4. Segmentation & Employee Context | B36: SEG-03 | C36: جداسازی Context از هویت نمایشی | D36: سیستم بتواند از Context سازمانی برای تحلیل استفاده کند بدون اینکه نام یا شماره فرد را در Dashboard عادی نمایش دهد. | E36: فیلتر سازمانی کار کند ولی جدول/نمودار نام یا شماره افراد را نشان ندهد. | G36: نیازمند تنظیم / Configuration | H36: جزئی | I36: coa/apps/users/permissions.py; coa/apps/main/services/call.py:849 (view_all_calls → agent_id scoping) | J36: قطعی | K36: MCINEXT | L36: T+10 روز کاری | M36: RBAC و Row-level scoping واقعی موجود است؛ پنهان‌سازی هویت در لایه Serializer لازم است
A37: 4. Segmentation & Employee Context | B37: SEG-04 | C37: Refresh / به‌روزرسانی دیتاست | D37: فرایند به‌روزرسانی Whitelist و Mapping کارکنان مشخص باشد تا جابه‌جایی سازمانی یا تغییر شماره باعث استفاده از داده قدیمی نشود. | E37: روش Refresh، تناوب و مسئول به‌روزرسانی مستند شود. | G37: نیازمند تنظیم / Configuration | H37: غایب (فرایند) | I37: — | J37: قطعی | K37: مشترک | L37: T+5 روز کاری پس از توافق تناوب | M37: فرایند و مسئول، نه کد
A38: 4. Segmentation & Employee Context | B38: SEG-05 | C38: مدیریت Mapping ناموفق | D38: اگر شماره داخل Whitelist باشد ولی Context سازمانی آن قابل بازیابی نباشد، سیستم رکورد را Unmapped علامت بزند و از نسبت‌دادن حدسی جلوگیری کند. | E38: نمونه Unmapped در گزارش خطا/داده دیده شود و به واحد اشتباه نسبت داده نشود. | G38: موجود در محصول | H38: جزئی | I38: هیچ برچسب Unmapped در مدل داده یافت نشد | J38: محتمل | K38: MCINEXT | L38: T+7 روز کاری | M38: در توافق «موجود» علامت خورده اما شاهد کدی پیدا نشد — پیش از UAT تأیید کنید
A39: 4. Segmentation & Employee Context | B39: SEG-06 | C39: محدودیت جامعه Pilot به قرارداد MCI | D39: در نسخه اول Segmentها فقط برای جامعه MCI تحلیل شوند؛ گروه‌های قراردادی دیگر تا تعیین Source و Mapping معتبر خارج از Pilot بمانند. | E39: هیچ رکورد غیر-MCI بدون تصمیم جدید وارد جامعه Pilot نشود. | G39: نیازمند تنظیم / Configuration | H39: تنظیم | I39: — | J39: قطعی | K39: EX | L39: T+3 روز کاری | M39: محدودسازی جامعه پایلوت
A40: 4. Segmentation & Employee Context | B40: SEG-07 | C40: اتصال مستقیم به SAP و همگام‌سازی خودکار اطلاعات کارکنان | D40: سامانه به‌جای دریافت و به‌روزرسانی دستی فایل Excel کارکنان، به SAP یا سرویس واسط مورد تأیید متصل شود و اطلاعات موردنیاز کارکنان را به‌صورت خودکار دریافت و به‌روزرسانی کند. با ایجاد، جابه‌جایی یا خروج همکار در SAP، اطلاعات سامانه نیز براساس زمان‌بندی یا مکانیزم Sync مورد توافق به‌روزرسانی شود. | E40: پس از تغییر اطلاعات یک کارمند در SAP، مانند جابه‌جایی از یک اداره به اداره دیگر، اطلاعات او بدون بارگذاری Excel و در بازه زمانی توافق‌شده در سامانه EX به‌روزرسانی شود. خطاهای Sync نیز قابل مشاهده و پیگیری باشند. | G40: نیازمند توسعه / Customization | H40: غایب | I40: هیچ کد SAP/middleware یافت نشد | J40: قطعی | K40: MCI-IT (اعطای دسترسی) | L40: Phase 2 — T+30 روز کاری پس از اعطای دسترسی SAP | M40: ⚠️ بزرگ‌ترین آیتم توسعه کل توافق و خارج از کنترل تیم شما. جایگزین MVP: SEG-01 + SEG-04 (اکسل + تناوب مستند)
...

Sheet خلاصه
A1: خلاصه وضعیت — محاسبه زنده از شیت «ردیف‌ها»
A3: دسته | B3: تعداد | C3: درصد | D3: تفسیر
A4: — وضعیت اعلامی در توافق —
A5: موجود در محصول | B5: =COUNTIF('ردیف‌ها'!$G$2:$G$88,"موجود در محصول") | C5: =IFERROR(COUNTIF('ردیف‌ها'!$G$2:$G$88,"موجود در محصول")/87,"") | D5: ادعای «ساخته شده» — بیشترین فشار UAT روی این‌هاست
A6: نیازمند تنظیم / Configuration | B6: =COUNTIF('ردیف‌ها'!$G$2:$G$88,"نیازمند تنظیم / Configuration") | C6: =IFERROR(COUNTIF('ردیف‌ها'!$G$2:$G$88,"نیازمند تنظیم / Configuration")/87,"") | D6: بدون کد جدید؛ سریع‌ترین بخش
A7: نیازمند توسعه / Customization | B7: =COUNTIF('ردیف‌ها'!$G$2:$G$88,"نیازمند توسعه / Customization") | C7: =IFERROR(COUNTIF('ردیف‌ها'!$G$2:$G$88,"نیازمند توسعه / Customization")/87,"") | D7: توسعه واقعی؛ منبع اصلی ریسک زمان‌بندی
A8: نیازمند بررسی فنی | B8: =COUNTIF('ردیف‌ها'!$G$2:$G$88,"نیازمند بررسی فنی") | C8: =IFERROR(COUNTIF('ردیف‌ها'!$G$2:$G$88,"نیازمند بررسی فنی")/87,"") | D8: باید به آیتم برآوردشده تبدیل شود
A9: فعلاً خارج از Scope | B9: =COUNTIF('ردیف‌ها'!$G$2:$G$88,"فعلاً خارج از Scope") | C9: =IFERROR(COUNTIF('ردیف‌ها'!$G$2:$G$88,"فعلاً خارج از Scope")/87,"") | D9: هر دو ردیف با کد نمی‌خوانند — AI-02 و PRV-08
A10: بدون وضعیت (خالی) | B10: =COUNTBLANK('ردیف‌ها'!$G$2:$G$88) | C10: =IFERROR(COUNTBLANK('ردیف‌ها'!$G$2:$G$88)/87,"") | D10: KB-02 و TEC-12 تا TEC-15
A12: — وضعیت تأییدشده با کد —
A13: تأییدشده | B13: =COUNTIF('ردیف‌ها'!$H$2:$H$88,"تأییدشده*") | C13: =IFERROR(COUNTIF('ردیف‌ها'!$H$2:$H$88,"تأییدشده*")/87,"") | D13: در کد اثبات شد — قابل دفاع
A14: جزئی | B14: =COUNTIF('ردیف‌ها'!$H$2:$H$88,"جزئی*") | C14: =IFERROR(COUNTIF('ردیف‌ها'!$H$2:$H$88,"جزئی*")/87,"") | D14: بخشی پیاده — نیازمند توضیح دقیق در جلسه
A15: رد شد | B15: =COUNTIF('ردیف‌ها'!$H$2:$H$88,"رد شد*") | C15: =IFERROR(COUNTIF('ردیف‌ها'!$H$2:$H$88,"رد شد*")/87,"") | D15: ادعای توافق نادرست — پیش از جلسه اصلاح شود
A16: غایب | B16: =COUNTIF('ردیف‌ها'!$H$2:$H$88,"غایب*") | C16: =IFERROR(COUNTIF('ردیف‌ها'!$H$2:$H$88,"غایب*")/87,"") | D16: هیچ کدی نیست — توسعه واقعی
A17: نامشخص | B17: =COUNTIF('ردیف‌ها'!$H$2:$H$88,"نامشخص*") | C17: =IFERROR(COUNTIF('ردیف‌ها'!$H$2:$H$88,"نامشخص*")/87,"") | D17: در coa-ai فریزشده — بدون داده سرعت تیم
A18: تنظیم | B18: =COUNTIF('ردیف‌ها'!$H$2:$H$88,"تنظیم*") | C18: =IFERROR(COUNTIF('ردیف‌ها'!$H$2:$H$88,"تنظیم*")/87,"") | D18: Configuration یا زیرساخت
A19: خارج از کد | B19: =COUNTIF('ردیف‌ها'!$H$2:$H$88,"خارج از کد*") | C19: =IFERROR(COUNTIF('ردیف‌ها'!$H$2:$H$88,"خارج از کد*")/87,"") | D19: فرایند یا وظیفه EX
A20: خالی | B20: =COUNTIF('ردیف‌ها'!$H$2:$H$88,"خالی*") | C20: =IFERROR(COUNTIF('ردیف‌ها'!$H$2:$H$88,"خالی*")/87,"") | D20: ستون توافق خالی است
A22: — وابستگی —
A23: EX | B23: =COUNTIF('ردیف‌ها'!$K$2:$K$88,"EX*") | C23: =IFERROR(COUNTIF('ردیف‌ها'!$K$2:$K$88,"EX*")/87,"") | D23: ساعت شما شروع نمی‌شود تا EX ورودی را تحویل دهد
A24: MCINEXT | B24: =COUNTIF('ردیف‌ها'!$K$2:$K$88,"MCINEXT*") | C24: =IFERROR(COUNTIF('ردیف‌ها'!$K$2:$K$88,"MCINEXT*")/87,"") | D24: تعهد مستقیم تیم شما
A25: مشترک | B25: =COUNTIF('ردیف‌ها'!$K$2:$K$88,"مشترک*") | C25: =IFERROR(COUNTIF('ردیف‌ها'!$K$2:$K$88,"مشترک*")/87,"") | D25: نیازمند تصمیم دوطرفه
A26: MCI-IT | B26: =COUNTIF('ردیف‌ها'!$K$2:$K$88,"MCI-IT*") | C26: =IFERROR(COUNTIF('ردیف‌ها'!$K$2:$K$88,"MCI-IT*")/87,"") | D26: خارج از کنترل هر دو تیم — مثل دسترسی SAP
A28: یادداشت | D28: درصدها با فرمول COUNTIF محاسبه می‌شوند؛ اگر وضعیتی را در شیت «ردیف‌ها» تغییر دهید این جدول خودکار به‌روز می‌شود. ستاره در الگوی جست‌وجو به معنای «شروع‌شده با» است.

Sheet یافته‌های بحرانی
A1: یافته‌های بحرانی از خوانش کد
A3: # | B3: عنوان | C3: شاهد در کد | D3: معنا برای کسب‌وکار | E3: اقدام
A4: ۱ | B4: IDOR روی فایل صوتی خام | C4: coa/apps/files/views.py:19 — @with_permissions({view_calls}) و سپس minio.download(name) بدون بررسی مالکیت | D4: هر کاربر دارای view_calls می‌تواند صوت هر تماسی را دانلود کند. نام فایل از call_id مشتق می‌شود. ردیف PRV-03 «موجود» علامت خورده و نیست. روی داده صوتی کارکنان، این یافته می‌تواند پایلوت را متوقف کند. | E4: ⛔ اصلاح پیش از UAT — T+3 روز کاری
A5: ۲ | B5: Transcript ذخیره می‌شود ولی «خارج از Scope» اعلام شده | C5: coa/apps/main/models.py:397 (raw_input) · services/call.py:771 · chatbot-iva-agent/src/schema.py (messages[].text) | D5: متن مکالمه ذخیره و روی Kafka منتشر می‌شود و حتی transcript_confidence دارد. ادعای AI-02 و دلیل PRV-08 نادرست است. هم اعتبار فنی را می‌برد و هم یک ریسک حریم خصوصی اعلام‌نشده ایجاد می‌کند. | E5: تصمیم سیاست در ۲ روز: نگهداری و اعلام، یا توقف ذخیره
A6: ۳ | B6: Audit Log وجود ندارد | C6: جست‌وجوی audit|LogEntry|access_log|viewed_by|actor_id در ۸ سرویس → صفر نتیجه | D6: ردیف PRV-06 «موجود» علامت خورده است. آنچه هست coa/middlewares.py:26 است که لاگ زیرساختی است نه Audit Trail قابل کوئری. ضمناً همان میدل‌ویر تمام هدرها را لاگ می‌کند؛ یعنی توکن‌های Authorization وارد لاگ می‌شوند. | E6: Downgrade در توافق + برآورد T+10 روز کاری
A7: ۴ | B7: موتور تحلیل ۱۴ ماه فریز است | C7: python/coa-ai — آخرین کامیت 2025-07-13، در حالی که coa-api در 2026-09-27 کامیت دارد | D7: تمام ردیف‌های کیفیت بلوک ۳ (AI-04 تا AI-07، AI-12، AI-13) از کدی می‌گذرند که هیچ داده سرعتِ به‌روز ندارد. برای این بلوک ددلاین تهاجمی ندهید. | E7: بازفعال‌سازی یا تأیید پایداری پیش از تعهد
A8: ۵ | B8: هیچ سنجش کیفیتی برای AIVA و CCA وجود ندارد | C8: تنها Eval موجود: aqa POST /api/v1/eval/run — هیچ معادلی برای WER، Faithfulness یا دقت Theme نیست | D8: ۴۳ ردیف «موجود در محصول» شامل ۱۱ ادعای کیفیتی است. «موجود» یعنی implemented نه measured، ولی EX آن را measured تست می‌کند (معیار AI-06 صریحاً مقایسه با نمونه Human-coded است). | E8: Golden Set حداقلی پیش از UAT
A9: ۶ | B9: خبر خوب: Pruner مخرب وجود ندارد | C9: تمام مسیرهای حذف بررسی شد: archive_old_calls.py (آرشیو→حذف) · trends/services/sync.py:388 (بازسازی کامل) · services/call.py:448 | D9: آنچه روی وایت‌بورد به‌عنوان «حذف topic و تماس‌هایش» طراحی شده بود پیاده نشده است. همچنین TrendAnnotation عمداً denormalize شده تا یادداشت‌های انسانی از بازسازی جان سالم ببرند. | E9: اقدامی لازم نیست — این را به‌عنوان نقطه قوت ارائه کنید
A10: ۷ | B10: خبر خوب: Retention بهتر از ادعاست | C10: archive_old_calls.py — pg_dump → MinIO → حذف → VACUUM، با abort-on-failure و --dry-run | D10: PRV-07 درست است و PRV-08 هم عملاً پوشش داده شده چون call_ai_tags هم آرشیو و حذف می‌شود. شما دارید کمتر از توان واقعی‌تان ادعا می‌کنید. | E10: PRV-08 را از «خارج از Scope» خارج کنید
A11: ۸ | B11: خبر خوب: پیامک ساخته شده | C11: aiva/tools/sms.py → POST resan.mci.dev/api/messages/send/to/ · در AGENT_ENABLED_TOOLS پیش‌فرض فعال | D11: KB-06 به‌اشتباه «نیازمند توسعه» علامت خورده است. اما LLM خودش تصمیم ارسال می‌گیرد، پس وابستگی واقعی «سناریوهای EX» یک نیاز Guardrail است نه یک نیاز یکپارچه‌سازی. | E11: ارتقا به «موجود» + Rate limit در T+5 روز کاری
A12: ۹ | B12: Whitelist هست ولی جای اشتباه | C12: aiva/memory/config.py:20-21 — PHONE_WHITELIST=[] و BYPASS_WHITELIST=True · aiva_consume_kafka.py:310 | D12: این Whitelist فقط «جمع‌آوری memory» را گیت می‌کند، نه «پذیرش تماس». نیاز VIA-02 پذیرش تماس است که باید در لایه SIP پیاده شود. ضمناً پیش‌فرض روی Bypass است. | E12: گیت SIP + پرکردن PHONE_WHITELIST و BYPASS_WHITELIST=false
A13: ۱۰ | B13: AQA قوی‌ترین دارایی نمایشی شماست | C13: python/aqa — 9,119 خط · POST /api/v1/chat/message (SSE) · /configs/prompts قابل ویرایش در Runtime · /eval/run | D13: ردیف AN-12 (دستیار تحلیل با زبان طبیعی) که بلندپروازانه‌ترین ردیف توافق است، واقعاً ساخته شده و تنها سرویسی است که Eval Harness دارد. | E13: در جلسه Demo زنده بگیرید
A14: ۱۱ | B14: Long-term Memory بین تماس‌ها | C14: aiva/memory/management/commands/aiva_consume_kafka.py · ChatbotUser.memory · aiva/chat/views/session.py | D14: پس از هر تماس یک خلاصه از کاربر ساخته و در تماس بعدی به Context داده می‌شود؛ شماره و Memory در Tracing Span هم ثبت می‌شوند. برای کارکنان یک تصمیم Privacy است. | E14: اعلام در Privacy Notice یا خاموش‌کردن Consumer برای EX
... A16: ۱۳ | B16: AQA مسیر دوم به هویت | C16: aqa/agents/tools/sql_executor.py — Query آزاد، Read-only فقط با کاربر DB | D16: PRV-02 «هر مسیر دیگر» بازیابی هویت را منع می‌کند؛ AQA می‌تواند ستون شماره را برگرداند. | E16: View بدون ستون هویتی برای کاربر DB مخصوص AQA

Sheet معماری
A1: سرویس‌های فعال پایتون — کامیت در ۳ ماه گذشته
A3: سرویس | B3: خط کد | C3: فایل | D3: نقش | E3: آخرین کامیت
A4: python/coa-api | B4: 31596 | C4: 325 | D4: لایه سرویس‌دهی CCA — تحلیل، Trend، تیکت، کارشناس، داشبورد IVA، Sync با ClickHouse، آرشیو | E4: 2026-09-27
A5: python/agentlib | B5: 19188 | C5: 444 | D5: کتابخانه هسته Agent — LLM، ابزار، ReAct، Monitoring. ۱۴۰ فایل تست | E5: 2026-09-27
A6: python/aiva | B6: 11492 | C6: 121 | D6: مغز چت IVA — Orchestrator رویدادمحور: Guardrail، Intent، Classification، Clarifying، VoiceBridge، ReAct | E6: 2026-09-28
A7: python/adcs | B7: 11411 | C7: 230 | D7: نسل قبلی/موازی aiva — Chat API، پروکسی ASR/TTS، داشبورد چت، بازخورد | E7: 2026-09-25
A8: python/aqa | B8: 9119 | C8: 156 | D8: Agentic Query Analyzer — تبدیل زبان طبیعی به SQL روی داده تحلیلی. دارای Eval | E8: 2026-09-27
A9: python/chatbot-iva-agent | B9: 5671 | C9: 26 | D9: Agent صوتی Realtime روی LiveKit — SIP، VAD، Turn detection، STT/TTS، ضبط، Kafka | E9: 2026-09-28
A10: python/adcs-knowledgebase | B10: 4716 | C10: 84 | D10: میکروسرویس دانش — CRUD سؤال/پاسخ، Guardrail، Tag، Summarize، Import/Export | E10: فعال
A11: python/adcs-auth | B11: 2610 | C11: 67 | D11: احراز هویت مرکزی — صدور JWT. ⚠️ صفر فایل تست | E11: فعال
A12: python/fastlib | B12: 1740 | C12: 40 | D12: زیرساخت مشترک FastAPI — لاگ درخواست، پوشش خطا، healthz | E12: فعال
A13: python/aiva-knowledgebase | B13: 730 | C13: 17 | D13: میکروسرویس دانش AIVA — Embedding با کلاینت OpenAI-compatible | E13: فعال
A14: golang/grogu | B14: — | C14: — | D14: Ingestion اصلی CCA (Go): Kafka، MinIO، ASR با Circuit Breaker، MyMCI، Upsert در Postgres، Dead-letter | E14: 2026-09-27
A15: golang/neurobox-gateway | B15: — | C15: — | D15: Gateway مدل‌های ASR/TTS روی Triton (gRPC) | E15: 2026-09-13
A16: golang/websocall | B16: — | C16: — | D16: Voice روی WebSocket برای مرورگر | E16: 2026-09-28
A17: golang/dobby | B17: — | C17: — | D17: MCP Server برای Toolهای AIVA | E17: 2026-09-27
A18: python/coa-ai | B18: — | C18: — | D18: ⚠️ موتور تحلیل (احساسات، خلاصه، موضوع) — خارج از دامنه بررسی، ۱۴ ماه فریز | E18: 2025-07-13
A20: زیرساخت داده
A21: PostgreSQL | D21: ۱۹ جدول اصلی: voices، calls، call_ai_tags، call_records، trends، subjects، trend_annotations، tickets، experts …
A22: ClickHouse | D22: منبع نتایج تحلیل؛ چهار Daemon همگام‌سازی: clickhouse_sync، clickhouse_update_sync، failed_calls_sync، sync_canonical_mappings
A23: Qdrant (gRPC) | D23: کالکشن‌های AIVA: guardrail، aiva-contexts، aiva-instructions، aiva-classification، aiva-jokes — آستانه و top-k قابل تنظیم
A24: MinIO / S3 | D24: باکت chatbot-mci-iva برای ضبط تماس + مقصد آرشیو pg_dump
A25: Kafka | D25: تولید: chatbot-mci-iva (از Agent صوتی) · مصرف: chatbot-mci-iva-intent (ماژول memory در aiva)
A26: مدل‌های LLM | D26: google/gemma-4-31B-it (میزبانی داخلی) و openai/gpt-oss-120b — هفت نقش مستقل و هرکدام جداگانه قابل تنظیم
A27: رصدپذیری | D27: Prometheus، Elastic APM، Phoenix/OpenTelemetry tracing
